Authenticated
Traceback (most recent call last):
  File "AntonioMagrina.py", line 330, in <module>
    mybot.retweet_keyword()
  File "AntonioMagrina.py", line 265, in retweet_keyword
    sleep(14400)
KeyboardInterrupt
Authenticated
Traceback (most recent call last):
  File "AllenWinston.py", line 330, in <module>
    mybot.retweet_keyword()
  File "AllenWinston.py", line 265, in retweet_keyword
    sleep(14400)
KeyboardInterrupt
Authenticated
Traceback (most recent call last):
  File "WyattFulke.py", line 331, in <module>
    mybot.retweet_keyword()
  File "WyattFulke.py", line 266, in retweet_keyword
    sleep(14400)
KeyboardInterrupt
python: can't open file 'ClaytonMcClellan': [Errno 2] No such file or directory
python: can't open file 'ClaytonMcClellan.py': [Errno 2] No such file or directory
Authenticated
Traceback (most recent call last):
  File "ClaytonMacClellan.py", line 328, in <module>
    mybot.retweet_keyword()
  File "ClaytonMacClellan.py", line 259, in retweet_keyword
    image, description = self.analyze_image()
  File "ClaytonMacClellan.py", line 211, in analyze_image
    image_caption = analysis["description"]["captions"][0]["text"].capitalize()
IndexError: list index out of range
Authenticated
Traceback (most recent call last):
  File "ClaytonMacClellan.py", line 328, in <module>
    mybot.retweet_keyword()
  File "ClaytonMacClellan.py", line 259, in retweet_keyword
    image, description = self.analyze_image()
  File "ClaytonMacClellan.py", line 211, in analyze_image
    image_caption = analysis["description"]["captions"][0]["text"].capitalize()
IndexError: list index out of range
Authenticated
Traceback (most recent call last):
  File "ClaytonMacClellan.py", line 328, in <module>
    mybot.retweet_keyword()
  File "ClaytonMacClellan.py", line 292, in retweet_keyword
    reply = self.GREETING[greet_index] + ' https://twitter.com/'+tweet.user.screen_name+'/status/'+tweet.id_str
UnicodeDecodeError: 'ascii' codec can't decode byte 0xe2 in position 213: ordinal not in range(128)
Authenticated
[{u'message': u'You have already favorited this status.', u'code': 139}]
[{u'message': u'You have already favorited this status.', u'code': 139}]
[{u'message': u'You have already favorited this status.', u'code': 139}]
Traceback (most recent call last):
  File "AllenWinston.py", line 330, in <module>
    mybot.retweet_keyword()
  File "AllenWinston.py", line 294, in retweet_keyword
    reply = self.GREETING[greet_index] + ' https://twitter.com/'+tweet.user.screen_name+'/status/'+tweet.id_str
UnicodeDecodeError: 'ascii' codec can't decode byte 0xe2 in position 27: ordinal not in range(128)
Authenticated
[{u'message': u'You have already favorited this status.', u'code': 139}]
[{u'message': u'You have already favorited this status.', u'code': 139}]
[{u'message': u'You have already favorited this status.', u'code': 139}]
[{u'message': u'You have already favorited this status.', u'code': 139}]
[{u'message': u'You have already favorited this status.', u'code': 139}]
[{u'message': u'You have already favorited this status.', u'code': 139}]
[{u'message': u'You have already favorited this status.', u'code': 139}]
Traceback (most recent call last):
  File "WyattFulke.py", line 331, in <module>
    mybot.retweet_keyword()
  File "WyattFulke.py", line 295, in retweet_keyword
    reply = self.GREETING[greet_index] + ' https://twitter.com/'+tweet.user.screen_name+'/status/'+tweet.id_str
UnicodeDecodeError: 'ascii' codec can't decode byte 0xe2 in position 213: ordinal not in range(128)
Authenticated
[{u'message': u'You have already favorited this status.', u'code': 139}]
[{u'message': u'You have already favorited this status.', u'code': 139}]
[{u'message': u'You have already favorited this status.', u'code': 139}]
[{u'message': u'You have already favorited this status.', u'code': 139}]
[{u'message': u'You have already favorited this status.', u'code': 139}]
[{u'message': u'You have already favorited this status.', u'code': 139}]
[{u'message': u'You have already favorited this status.', u'code': 139}]
[{u'message': u'You have already favorited this status.', u'code': 139}]
Traceback (most recent call last):
  File "ChristinaAbles.py", line 330, in <module>
    mybot.retweet_keyword()
  File "ChristinaAbles.py", line 294, in retweet_keyword
    reply = self.GREETING[greet_index] + ' https://twitter.com/'+tweet.user.screen_name+'/status/'+tweet.id_str
UnicodeDecodeError: 'ascii' codec can't decode byte 0xe2 in position 213: ordinal not in range(128)
Authenticated
Traceback (most recent call last):
  File "annepoirier.py", line 328, in <module>
    mybot.retweet_keyword()
  File "annepoirier.py", line 259, in retweet_keyword
    image, description = self.analyze_image()
  File "annepoirier.py", line 208, in analyze_image
    response.raise_for_status()
  File "/usr/local/lib/python2.7/dist-packages/requests/models.py", line 939, in raise_for_status
    raise HTTPError(http_error_msg, response=self)
requests.exceptions.HTTPError: 400 Client Error: Bad Request for url: https://eastus.api.cognitive.microsoft.com/vision/v1.0/analyze?visualFeatures=Categories%2CDescription%2CColor
Authenticated
Traceback (most recent call last):
  File "mattwruck.py", line 328, in <module>
    mybot.retweet_keyword()
  File "mattwruck.py", line 259, in retweet_keyword
    image, description = self.analyze_image()
  File "mattwruck.py", line 211, in analyze_image
    image_caption = analysis["description"]["captions"][0]["text"].capitalize()
IndexError: list index out of range
Authenticated
[{u'message': u'You have already favorited this status.', u'code': 139}]
Traceback (most recent call last):
  File "emilymathers.py", line 326, in <module>
    mybot.retweet_keyword()
  File "emilymathers.py", line 260, in retweet_keyword
    self.api.update_with_media(image, status=message)
  File "/usr/local/lib/python2.7/dist-packages/tweepy/api.py", line 219, in update_with_media
    headers, post_data = API._pack_image(filename, 3072, form_field='media[]', f=f)
  File "/usr/local/lib/python2.7/dist-packages/tweepy/api.py", line 1301, in _pack_image
    raise TweepError('File is too big, must be less than %skb.' % max_size)
tweepy.error.TweepError: File is too big, must be less than 3072kb.
Authenticated
[{u'message': u'You have already favorited this status.', u'code': 139}]
[{u'message': u'You have already favorited this status.', u'code': 139}]
[{u'message': u'You have already favorited this status.', u'code': 139}]
[{u'message': u'You have already favorited this status.', u'code': 139}]
[{u'message': u'You have already favorited this status.', u'code': 139}]
[{u'message': u'You have already favorited this status.', u'code': 139}]
[{u'message': u'You have already favorited this status.', u'code': 139}]
[{u'message': u'You have already favorited this status.', u'code': 139}]
Traceback (most recent call last):
  File "renedaniel.py", line 325, in <module>
    mybot.retweet_keyword()
  File "renedaniel.py", line 259, in retweet_keyword
    self.api.update_with_media(image, status=message)
  File "/usr/local/lib/python2.7/dist-packages/tweepy/api.py", line 219, in update_with_media
    headers, post_data = API._pack_image(filename, 3072, form_field='media[]', f=f)
  File "/usr/local/lib/python2.7/dist-packages/tweepy/api.py", line 1301, in _pack_image
    raise TweepError('File is too big, must be less than %skb.' % max_size)
tweepy.error.TweepError: File is too big, must be less than 3072kb.
